<?xml version="1.0"?>
<robot name="simple_humanoid">

  <!-- Materials -->
  <material name="blue">
    <color rgba="0 0 1 1"/>
  </material>
  <material name="white">
    <color rgba="1 1 1 1"/>
  </material>
  <material name="black">
    <color rgba="0 0 0 1"/>
  </material>
  <material name="red">
    <color rgba="1 0 0 1"/>
  </material>

  <!-- Base link (torso) -->
  <link name="base_link">
    <inertial>
      <origin xyz="0 0 0.3" rpy="0 0 0"/>
      <mass value="10"/>
      <inertia ixx="0.5" ixy="0" ixz="0" iyy="0.5" iyz="0" izz="0.2"/>
    </inertial>

    <visual>
      <origin xyz="0 0 0.3" rpy="0 0 0"/>
      <geometry>
        <box size="0.3 0.3 0.6"/>
      </geometry>
      <material name="white"/>
    </visual>

    <collision>
      <origin xyz="0 0 0.3" rpy="0 0 0"/>
      <geometry>
        <box size="0.3 0.3 0.6"/>
      </geometry>
    </collision>
  </link>

  <!-- Head -->
  <joint name="base_link_to_head" type="fixed">
    <origin xyz="0 0 0.65" rpy="0 0 0"/>
    <parent link="base_link"/>
    <child link="head"/>
  </joint>

  <link name="head">
    <inertial>
      <origin xyz="0 0 0" rpy="0 0 0"/>
      <mass value="1"/>
      <inertia ixx="0.01" ixy="0" ixz="0" iyy="0.01" iyz="0" izz="0.01"/>
    </inertial>

    <visual>
      <origin xyz="0 0 0" rpy="0 0 0"/>
      <geometry>
        <sphere radius="0.1"/>
      </geometry>
      <material name="white"/>
    </visual>

    <collision>
      <origin xyz="0 0 0" rpy="0 0 0"/>
      <geometry>
        <sphere radius="0.1"/>
      </geometry>
    </collision>
  </link>

  <!-- Left Arm -->
  <joint name="base_link_to_left_shoulder" type="revolute">
    <origin xyz="0.2 0 0.4" rpy="0 0 0"/>
    <parent link="base_link"/>
    <child link="left_upper_arm"/>
    <axis xyz="0 1 0"/>
    <limit lower="-1.57" upper="1.57" effort="100" velocity="1"/>
  </joint>

  <link name="left_upper_arm">
    <inertial>
      <origin xyz="0 0 -0.1" rpy="0 0 0"/>
      <mass value="2"/>
      <inertia ixx="0.02" ixy="0" ixz="0" iyy="0.02" iyz="0" izz="0.01"/>
    </inertial>

    <visual>
      <origin xyz="0 0 -0.1" rpy="0 0 0"/>
      <geometry>
        <cylinder radius="0.05" length="0.2"/>
      </geometry>
      <material name="blue"/>
    </visual>

    <collision>
      <origin xyz="0 0 -0.1" rpy="0 0 0"/>
      <geometry>
        <cylinder radius="0.05" length="0.2"/>
      </geometry>
    </collision>
  </link>

  <joint name="left_shoulder_to_elbow" type="revolute">
    <origin xyz="0 0 -0.2" rpy="0 0 0"/>
    <parent link="left_upper_arm"/>
    <child link="left_lower_arm"/>
    <axis xyz="0 1 0"/>
    <limit lower="-1.57" upper="1.57" effort="100" velocity="1"/>
  </joint>

  <link name="left_lower_arm">
    <inertial>
      <origin xyz="0 0 -0.1" rpy="0 0 0"/>
      <mass value="1.5"/>
      <inertia ixx="0.01" ixy="0" ixz="0" iyy="0.01" iyz="0" izz="0.005"/>
    </inertial>

    <visual>
      <origin xyz="0 0 -0.1" rpy="0 0 0"/>
      <geometry>
        <cylinder radius="0.04" length="0.2"/>
      </geometry>
      <material name="blue"/>
    </visual>

    <collision>
      <origin xyz="0 0 -0.1" rpy="0 0 0"/>
      <geometry>
        <cylinder radius="0.04" length="0.2"/>
      </geometry>
    </collision>
  </link>

  <!-- Right Arm -->
  <joint name="base_link_to_right_shoulder" type="revolute">
    <origin xyz="-0.2 0 0.4" rpy="0 0 0"/>
    <parent link="base_link"/>
    <child link="right_upper_arm"/>
    <axis xyz="0 1 0"/>
    <limit lower="-1.57" upper="1.57" effort="100" velocity="1"/>
  </joint>

  <link name="right_upper_arm">
    <inertial>
      <origin xyz="0 0 -0.1" rpy="0 0 0"/>
      <mass value="2"/>
      <inertia ixx="0.02" ixy="0" ixz="0" iyy="0.02" iyz="0" izz="0.01"/>
    </inertial>

    <visual>
      <origin xyz="0 0 -0.1" rpy="0 0 0"/>
      <geometry>
        <cylinder radius="0.05" length="0.2"/>
      </geometry>
      <material name="blue"/>
    </visual>

    <collision>
      <origin xyz="0 0 -0.1" rpy="0 0 0"/>
      <geometry>
        <cylinder radius="0.05" length="0.2"/>
      </geometry>
    </collision>
  </link>

  <joint name="right_shoulder_to_elbow" type="revolute">
    <origin xyz="0 0 -0.2" rpy="0 0 0"/>
    <parent link="right_upper_arm"/>
    <child link="right_lower_arm"/>
    <axis xyz="0 1 0"/>
    <limit lower="-1.57" upper="1.57" effort="100" velocity="1"/>
  </joint>

  <link name="right_lower_arm">
    <inertial>
      <origin xyz="0 0 -0.1" rpy="0 0 0"/>
      <mass value="1.5"/>
      <inertia ixx="0.01" ixy="0" ixz="0" iyy="0.01" iyz="0" izz="0.005"/>
    </inertial>

    <visual>
      <origin xyz="0 0 -0.1" rpy="0 0 0"/>
      <geometry>
        <cylinder radius="0.04" length="0.2"/>
      </geometry>
      <material name="blue"/>
    </visual>

    <collision>
      <origin xyz="0 0 -0.1" rpy="0 0 0"/>
      <geometry>
        <cylinder radius="0.04" length="0.2"/>
      </geometry>
    </collision>
  </link>

  <!-- Left Leg -->
  <joint name="base_link_to_left_hip" type="revolute">
    <origin xyz="0.07 0 0" rpy="0 0 0"/>
    <parent link="base_link"/>
    <child link="left_upper_leg"/>
    <axis xyz="0 1 0"/>
    <limit lower="-1.57" upper="1.57" effort="100" velocity="1"/>
  </joint>

  <link name="left_upper_leg">
    <inertial>
      <origin xyz="0 0 -0.2" rpy="0 0 0"/>
      <mass value="3"/>
      <inertia ixx="0.05" ixy="0" ixz="0" iyy="0.05" iyz="0" izz="0.01"/>
    </inertial>

    <visual>
      <origin xyz="0 0 -0.2" rpy="0 0 0"/>
      <geometry>
        <cylinder radius="0.06" length="0.4"/>
      </geometry>
      <material name="black"/>
    </visual>

    <collision>
      <origin xyz="0 0 -0.2" rpy="0 0 0"/>
      <geometry>
        <cylinder radius="0.06" length="0.4"/>
      </geometry>
    </collision>
  </link>

  <joint name="left_hip_to_knee" type="revolute">
    <origin xyz="0 0 -0.4" rpy="0 0 0"/>
    <parent link="left_upper_leg"/>
    <child link="left_lower_leg"/>
    <axis xyz="0 1 0"/>
    <limit lower="-1.57" upper="1.57" effort="100" velocity="1"/>
  </joint>

  <link name="left_lower_leg">
    <inertial>
      <origin xyz="0 0 -0.2" rpy="0 0 0"/>
      <mass value="2.5"/>
      <inertia ixx="0.03" ixy="0" ixz="0" iyy="0.03" iyz="0" izz="0.008"/>
    </inertial>

    <visual>
      <origin xyz="0 0 -0.2" rpy="0 0 0"/>
      <geometry>
        <cylinder radius="0.05" length="0.4"/>
      </geometry>
      <material name="black"/>
    </visual>

    <collision>
      <origin xyz="0 0 -0.2" rpy="0 0 0"/>
      <geometry>
        <cylinder radius="0.05" length="0.4"/>
      </geometry>
    </collision>
  </link>

  <!-- Right Leg -->
  <joint name="base_link_to_right_hip" type="revolute">
    <origin xyz="-0.07 0 0" rpy="0 0 0"/>
    <parent link="base_link"/>
    <child link="right_upper_leg"/>
    <axis xyz="0 1 0"/>
    <limit lower="-1.57" upper="1.57" effort="100" velocity="1"/>
  </joint>

  <link name="right_upper_leg">
    <inertial>
      <origin xyz="0 0 -0.2" rpy="0 0 0"/>
      <mass value="3"/>
      <inertia ixx="0.05" ixy="0" ixz="0" iyy="0.05" iyz="0" izz="0.01"/>
    </inertial>

    <visual>
      <origin xyz="0 0 -0.2" rpy="0 0 0"/>
      <geometry>
        <cylinder radius="0.06" length="0.4"/>
      </geometry>
      <material name="black"/>
    </visual>

    <collision>
      <origin xyz="0 0 -0.2" rpy="0 0 0"/>
      <geometry>
        <cylinder radius="0.06" length="0.4"/>
      </geometry>
    </collision>
  </link>

  <joint name="right_hip_to_knee" type="revolute">
    <origin xyz="0 0 -0.4" rpy="0 0 0"/>
    <parent link="right_upper_leg"/>
    <child link="right_lower_leg"/>
    <axis xyz="0 1 0"/>
    <limit lower="-1.57" upper="1.57" effort="100" velocity="1"/>
  </joint>

  <link name="right_lower_leg">
    <inertial>
      <origin xyz="0 0 -0.2" rpy="0 0 0"/>
      <mass value="2.5"/>
      <inertia ixx="0.03" ixy="0" ixz="0" iyy="0.03" iyz="0" izz="0.008"/>
    </inertial>

    <visual>
      <origin xyz="0 0 -0.2" rpy="0 0 0"/>
      <geometry>
        <cylinder radius="0.05" length="0.4"/>
      </geometry>
      <material name="black"/>
    </visual>

    <collision>
      <origin xyz="0 0 -0.2" rpy="0 0 0"/>
      <geometry>
        <cylinder radius="0.05" length="0.4"/>
      </geometry>
    </collision>
  </link>

</robot>